<?xml version="1.0"?>


<robot name = "delta_drv90l">

  <link name="base_link">
    <inertial>
      <origin xyz="0 0 0" rpy="0 0 0" />
      <mass value="1.0" />
      <inertia ixx="1" ixy="0" ixz="0"
                       iyy="1" iyz="0"
                               izz="1" />
    </inertial>
    <visual>
      <origin xyz="0 0 0" rpy="0 0 0" />
      <geometry>
        <mesh filename="delta_drv90l_support/meshes/drv90l/visual/base_link.STL"/>
      </geometry>
      <material name="visual_material">
        <color rgba="1 1 1 1"/>
      </material>
    </visual>
    <collision>
      <origin xyz="0 0 0" rpy="0 0 0" />
      <geometry>
        <mesh filename="delta_drv90l_support/meshes/drv90l/collision/base_link.STL"/>
      </geometry>
      <material name="collision_material">
        <color rgba="1 1 1 1"/>
      </material>
    </collision>
  </link>

  <link name="link_1">
    <inertial>
      <origin xyz="0 0 0" rpy="0 0 0" />
      <mass value="1.0" />
      <inertia ixx="1" ixy="0" ixz="0"
                       iyy="1" iyz="0"
                               izz="1" />
    </inertial>
    <visual>
      <origin xyz="0 0 0" rpy="0 0 0" />
      <geometry>
        <mesh filename="delta_drv90l_support/meshes/drv90l/visual/link_1.STL"/>
      </geometry>
      <material name="visual_material"/>
    </visual>
    <collision>
      <origin xyz="0 0 0" rpy="0 0 0" />
      <geometry>
        <mesh filename="delta_drv90l_support/meshes/drv90l/collision/link_1.STL"/>
      </geometry>
      <material name="collision_material"/>
    </collision>
  </link>

  <joint name="joint_1" type="revolute">
    <origin xyz="0 0 0.226" rpy="0 0 0" />
    <parent link="base_link"/>
    <child link="link_1"/>
    <axis xyz="0 0 1" />
    <limit
      lower="-2.96706"
      upper="2.96706"
      effort="0"
      velocity="1.028" />
  </joint>


  <link name="link_2">
    <inertial>
      <origin xyz="0 0 0" rpy="0 0 0" />
      <mass value="1.0" />
      <inertia ixx="1" ixy="0" ixz="0"
                       iyy="1" iyz="0"
                               izz="1" />
    </inertial>
    <visual>
      <origin xyz="0 0 0" rpy="0 0 0" />
      <geometry>
        <mesh filename="delta_drv90l_support/meshes/drv90l/visual/link_2.STL"/>
      </geometry>
      <material name="visual_material"/>
    </visual>
    <collision>
      <origin xyz="0 0 0" rpy="0 0 0" />
      <geometry>
        <mesh filename="delta_drv90l_support/meshes/drv90l/collision/link_2.STL"/>
      </geometry>
      <material name="collision_material"/>
    </collision>
  </link>

  <joint name="joint_2" type="revolute">
    <origin xyz="0.025 0 0.148" rpy="0 0 0" />
    <parent link="link_1"/>
    <child link="link_2"/>
    <axis xyz="0 1 0" />
    <limit
      lower="-1.8326"
      upper="2.35619"
      effort="0"
      velocity="0.7222" />
  </joint>

  <link name="link_3">
    <inertial>
      <origin xyz="0 0 0" rpy="0 0 0" />
      <mass value="1.0" />
      <inertia ixx="1" ixy="0" ixz="0"
                       iyy="1" iyz="0"
                               izz="1" />
    </inertial>
    <visual>
      <origin xyz="0 0 0" rpy="0 0 0" />
      <geometry>
        <mesh filename="delta_drv90l_support/meshes/drv90l/visual/link_3.STL"/>
      </geometry>
      <material name="visual_material"/>
    </visual>
    <collision>
      <origin xyz="0 0 0" rpy="0 0 0" />
      <geometry>
        <mesh filename="delta_drv90l_support/meshes/drv90l/collision/link_3.STL"/>
      </geometry>
      <material name="collision_material"/>
    </collision>
  </link>


  <joint name="joint_3" type="revolute">
    <origin xyz="0 0 0.44" rpy="0 0 0" />
    <parent link="link_2"/>
    <child link="link_3"/>
    <axis xyz="0 1 0" />
    <limit
      lower="-3.57792"
      upper="1.13446"
      effort="0"
      velocity="1.139" />
  </joint>

  <link name="link_4">
    <inertial>
      <origin xyz="0 0 0" rpy="0 0 0" />
      <mass value="1.0" />
      <inertia ixx="1" ixy="0" ixz="0"
                       iyy="1" iyz="0"
                               izz="1" />
    </inertial>
    <visual>
      <origin xyz="0 0 0" rpy="0 0 0" />
      <geometry>
        <mesh filename="delta_drv90l_support/meshes/drv90l/visual/link_4.STL"/>
      </geometry>
      <material name="visual_material"/>
    </visual>
    <collision>
      <origin xyz="0 0 0" rpy="0 0 0" />
      <geometry>
        <mesh filename="delta_drv90l_support/meshes/drv90l/collision/link_4.STL"/>
      </geometry>
      <material name="collision_material"/>
    </collision>
  </link>


  <joint name="joint_4" type="revolute">
    <origin xyz="0.145 0 0.04" rpy="0 0 0" />
    <parent link="link_3"/>
    <child link="link_4"/>
    <axis xyz="1 0 0" />
    <limit
      lower="-3.31613"
      upper="3.31613"
      effort="0"
      velocity="1.528" />
  </joint>


  <link name="link_5">
    <inertial>
      <origin xyz="0 0 0" rpy="0 0 0" />
      <mass value="1.0" />
      <inertia ixx="1" ixy="0" ixz="0"
                       iyy="1" iyz="0"
                               izz="1" />
    </inertial>
    <visual>
      <origin xyz="0 0 0" rpy="0 0 0" />
      <geometry>
        <mesh filename="delta_drv90l_support/meshes/drv90l/visual/link_5.STL"/>
      </geometry>
      <material name="visual_material"/>
    </visual>
    <collision>
      <origin xyz="0 0 0" rpy="0 0 0" />
      <geometry>
        <mesh filename="delta_drv90l_support/meshes/drv90l/collision/link_5.STL"/>
      </geometry>
      <material name="collision_material"/>
    </collision>
  </link>

  <joint name="joint_5" type="revolute">
    <origin xyz="0.29 0 0" rpy="0 0 0" />
    <parent link="link_4"/>
    <child link="link_5"/>
    <axis xyz="0 1 0" />
    <limit
      lower="-2.0944"
      upper="2.0944"
      effort="0"
      velocity="1.528" />
  </joint>


  <link name="link_6">
    <inertial>
      <origin xyz="0 0 0" rpy="0 0 0" />
      <mass value="1.0" />
      <inertia ixx="1" ixy="0" ixz="0"
                       iyy="1" iyz="0"
                               izz="1" />
    </inertial>
    <visual>
      <origin xyz="0 0 0" rpy="0 0 0" />
      <geometry>
        <mesh filename="delta_drv90l_support/meshes/drv90l/visual/link_6.STL"/>
      </geometry>
      <material name="visual_material"/>
    </visual>
    <collision>
      <origin xyz="0 0 0" rpy="0 0 0" />
      <geometry>
        <mesh filename="delta_drv90l_support/meshes/drv90l/collision/link_6.STL"/>
      </geometry>
      <material name="collision_material"/>
    </collision>
  </link>



  <joint name="joint_6" type="revolute">
    <origin xyz="0.064 0 0" rpy="0 0 0" />
    <parent link="link_5"/>
    <child link="link_6"/>
    <axis xyz="1 0 0" />
    <limit
      lower="-1.13446"
      upper="1.13446"
      effort="0"
      velocity="2.278" />
  </joint>


  <joint name="hand_joint" type="fixed">
    <parent link="link_6"/>
    <child link="hand"/>
    <axis xyz="0 0 1"/>
    <!-- change the rpy and xyz -->
    <origin rpy="0 1.57 0" xyz="0.013 0 0"/>
  </joint>

  <link name="hand">
  	<inertial>
      <origin rpy="0 0 0" xyz="0 0 0"/>
       <mass value=".81"/>
       <inertia ixx="0.1" ixy="0" ixz="0" iyy="0.1" iyz="0" izz="0.1"/>
    </inertial>
    <visual>
      <geometry>
        <mesh filename="delta_drv90l_support/meshes/drv90l/visual/hand.obj"/>
      </geometry>
      <material name="visual_material"/>
    </visual>
    <collision>
      <geometry>
        <mesh filename="delta_drv90l_support/meshes/drv90l/collision/hand.obj"/>
      </geometry>
      <material name="collision_material"/>
    </collision>
  </link>

  <link name="leftfinger">
    <contact>
      <friction_anchor/>
      <stiffness value="30000.0"/>
      <damping value="1000.0"/>
      <spinning_friction value="0.1"/>
      <lateral_friction value="1.0"/>
    </contact>
  	<inertial>
      <origin rpy="0 0 0" xyz="0 0.01 0.02"/>
       <mass value="0.1"/>
       <inertia ixx="0.1" ixy="0" ixz="0" iyy="0.1" iyz="0" izz="0.1"/>
    </inertial>
    <visual>
      <geometry>
        <!-- <mesh filename="package://meshes/visual/finger.obj"/> -->
        <mesh filename="delta_drv90l_support/meshes/drv90l/visual/finger_1.obj"/>
      </geometry>
      <material name="visual_material"/>
    </visual>
    <collision>
      <geometry>
        <!-- <mesh filename="package://meshes/collision/finger.obj"/> -->
        <mesh filename="delta_drv90l_support/meshes/drv90l/collision/finger_1.obj"/>
      </geometry>
      <material name="collision_material"/>
    </collision>
  </link>



  <link name="rightfinger">
    <contact>
      <friction_anchor/>
      <stiffness value="30000.0"/>
      <damping value="1000.0"/>
      <spinning_friction value="0.1"/>
      <lateral_friction value="1.0"/>
    </contact>

  	<inertial>
      <origin rpy="0 0 0" xyz="0 -0.01 0.02"/>
       <mass value="0.1"/>
       <inertia ixx="0.1" ixy="0" ixz="0" iyy="0.1" iyz="0" izz="0.1"/>
    </inertial>
    <visual>
      <origin rpy="0 0 3.14159265359" xyz="0 0 0"/>
      <geometry>
        <!-- <mesh filename="package://meshes/visual/finger.obj"/> -->
        <mesh filename="delta_drv90l_support/meshes/drv90l/visual/finger_1.obj"/>
      </geometry>
      <material name="visual_material"/>
    </visual>
    <collision>
      <origin rpy="0 0 3.14159265359" xyz="0 0 0"/>
      <geometry>
        <!-- <mesh filename="package://meshes/collision/finger.obj"/> -->
        <mesh filename="delta_drv90l_support/meshes/drv90l/collision/finger_1.obj"/>
      </geometry>
      <material name="collision_material"/>
    </collision>
  </link>


  <joint name="finger_joint1" type="prismatic">
    <parent link="hand"/>
    <child link="leftfinger"/>
    <origin rpy="0 0 0" xyz="0 0 0.0584"/>
    <axis xyz="0 1 0"/>
    <limit effort="50" lower="0.0" upper="0.04" velocity="0.2"/>
  </joint>

    <joint name="finger_joint2" type="prismatic">
    <parent link="hand"/>
    <child link="rightfinger"/>
    <origin rpy="0 0 0" xyz="0 0 0.0584"/>
    <axis xyz="0 -1 0"/>
    <limit effort="50" lower="0.0" upper="0.04" velocity="0.2"/>



  </joint>
   <link name="grasptarget">
    <inertial>
      <origin rpy="0 0 0" xyz="0 0 0"/>
       <mass value="0.0"/>
       <inertia ixx="0.1" ixy="0" ixz="0" iyy="0.1" iyz="0" izz="0.1"/>
    </inertial>
   </link>

      
   <joint name="grasptarget_hand" type="fixed">
    <parent link="hand"/>
    <child link="grasptarget"/>
    <origin rpy="0 0 0" xyz="0 0 0.105"/>
  </joint>

</robot>
