<?xml version="1.0" ?>
<robot name="gripper">

  <link name="base_link">
  	<inertial>
      <origin rpy="0 0 0" xyz="0 0 0.04"/>
       <mass value=".81"/>
       <inertia ixx="0.1" ixy="0" ixz="0" iyy="0.1" iyz="0" izz="0.1"/>
    </inertial>
    <visual>
      <geometry>
        <mesh filename="delta_drv90l_support/meshes/drv90l/visual/hand.obj"/>
      </geometry>
      <material name="panda_white1">
        <color rgba="1 1 1 0"/>
      </material>
    </visual>
  </link>

  <joint name="base_hand_joint" type="prismatic">
    <parent link="base_link"/>
    <child link="hand"/>
    <origin rpy="0 0 0" xyz="0 0 0"/>
    <axis xyz="0 0 1"/>
    <limit effort="50" lower="0.0" upper="10.0" velocity="0.2"/>
  </joint>

  <link name="hand">
  	<inertial>
      <origin rpy="0 0 0" xyz="0 0 0.04"/>
       <mass value=".81"/>
       <inertia ixx="0.1" ixy="0" ixz="0" iyy="0.1" iyz="0" izz="0.1"/>
    </inertial>
    <visual>
      <geometry>
        <mesh filename="delta_drv90l_support/meshes/drv90l/visual/hand.obj"/>
      </geometry>
      <material name="white"/>
    </visual>
    <!-- <collision> -->
    <collision group="0" mask="0">
      <geometry>
        <mesh filename="delta_drv90l_support/meshes/drv90l/collision/hand.obj"/>
      </geometry>
      <material name="white"/>
    </collision>
  </link>

  <link name="leftfinger">
    <contact>
      <friction_anchor/>
      <stiffness value="30000.0"/>
      <damping value="1000.0"/>
      <spinning_friction value="0.1"/>
      <lateral_friction value="1.0"/>
    </contact>
  	<inertial>
      <origin rpy="0 0 0" xyz="0 0.01 0.04"/>
       <mass value="0.1"/>
       <inertia ixx="0.1" ixy="0" ixz="0" iyy="0.1" iyz="0" izz="0.1"/>
    </inertial>
    <visual>
      <geometry>
        <mesh filename="delta_drv90l_support/meshes/drv90l/visual/finger_1.obj"/>
      </geometry>
      <material name="white"/>
    </visual>
    <!-- <collision> -->
    <collision group="0" mask="0">
      <geometry>
        <mesh filename="delta_drv90l_support/meshes/drv90l/visual/finger_1.obj"/>
      </geometry>
      <material name="white"/>
    </collision>
  </link>

  <link name="rightfinger">
    <contact>
      <friction_anchor/>
      <stiffness value="30000.0"/>
      <damping value="1000.0"/>
      <spinning_friction value="0.1"/>
      <lateral_friction value="1.0"/>
    </contact>

  	<inertial>
      <origin rpy="0 0 0" xyz="0 -0.01 0.04"/>
       <mass value="0.1"/>
       <inertia ixx="0.1" ixy="0" ixz="0" iyy="0.1" iyz="0" izz="0.1"/>
    </inertial>
    <visual>
      <origin rpy="0 0 3.14159265359" xyz="0 0 0"/>
      <geometry>
        <mesh filename="delta_drv90l_support/meshes/drv90l/visual/finger_1.obj"/>
      </geometry>
      <material name="white"/>
    </visual>
    <!-- <collision> -->
    <collision group="0" mask="0">
      <origin rpy="0 0 3.14159265359" xyz="0 0 0"/>
      <geometry>
        <mesh filename="delta_drv90l_support/meshes/drv90l/collision/finger_1.obj"/>
      </geometry>
      <material name="white"/>
    </collision>
  </link>

  <joint name="finger_joint1" type="prismatic">
    <parent link="hand"/>
    <child link="leftfinger"/>
    <!-- <origin rpy="0 0 0" xyz="0 0 0.0584"/> -->
    <origin rpy="0 0 0" xyz="0 -0.0035 0.0584"/>
    <axis xyz="0 1 0"/>
    <limit effort="50" lower="0.0" upper="0.1" velocity="0.2"/>
    <dynamics damping="40"/>
  </joint>

  <joint name="finger_joint2" type="prismatic">
    <parent link="hand"/>
    <child link="rightfinger"/>
    <origin rpy="0 0 0" xyz="0 0.0035 0.0584"/>
    <axis xyz="0 -1 0"/>
    <limit effort="50" lower="0.0" upper="0.1" velocity="0.2"/>
    <dynamics damping="40"/>
    <mimic joint="finger_joint1"/>
  </joint>
  
   <link name="grasptarget">
    <inertial>
      <origin rpy="0 0 0" xyz="0 0 0"/>
       <mass value="0.0"/>
       <inertia ixx="0.1" ixy="0" ixz="0" iyy="0.1" iyz="0" izz="0.1"/>
    </inertial>
   </link>
   
   <joint name="grasptarget_hand" type="fixed">
    <parent link="hand"/>
    <child link="grasptarget"/>
    <origin rpy="0 0 0" xyz="0 0 0.105"/>
  </joint>
  
</robot>
